const catchAsync = require('../utils/catchAsync');
const AppError = require('../utils/appError');

exports.deleteOne = (Model) =>
  catchAsync(async (req, res, next) => {
    const doc = await Model.findByIdAndDelete(req.params.id);

    if (!doc) {
      return next(new AppError('No document with that ID was found! ðŸ˜°', 404));
    }

    res.status(204).json({
      status: 'success',
      data: null,
    });
  });

exports.updateOne = (Model) =>
  catchAsync(async (req, res, next) => {
    const doc = await Model.findByIdAndUpdate(req.params.id, req.body, {
      new: true,
      runValidators: true,
    });

    if (!doc) {
      return next(new AppError('No document with that ID was found! ðŸ˜°', 404));
    }

    res.status(200).json({
      status: 'success',
      data: {
        data: doc,
      },
    });
  });

exports.createOne = (Model) =>
  catchAsync(async (req, res, next) => {
    const doc = await Model.create(req.body);

    // if (!product) {
    //   return next(new AppError('Error creating a product, try again!', 400));
    // }

    res.status(201).json({
      status: 'success',
      data: {
        data: doc,
      },
    });
  });
